<?xml version="1.0"?>
<robot name="continuum_robot">
<link name="base_link"/>
<material name="while">
<color rgba="0 1 0 1"/>
</material>

<link name="S0L0">
<visual>
<geometry>
<box size="1 1 0.5"/>
<origin rpy="0 0 0" xyz="0 0 0"/>
</geometry>
<material name="white"/>
</visual>
</link>

<joint name="S0J0" type="floating">
<parent link="base_link"/>
<child link="S0L0"/>
</joint>

<link name="S0L1">
<visual>
<geometry>
<cylinder length="0.1" radius="0.4"/>
<origin rpy="0 0 0" xyz="0 0 0"/>
</geometry>
</visual>
</link>

<joint name="S0J1" type="floating">
<parent link="base_link"/>
<child link="S0L1"/>
</joint>

<link name="S0L2">
<visual>
<geometry>
<cylinder length="0.1" radius="0.4"/>
<origin rpy="0 0 0" xyz="0 0 0"/>
</geometry>
</visual>
</link>

<joint name="S0J2" type="floating">
<parent link="base_link"/>
<child link="S0L2"/>
</joint>

<link name="S0L3">
<visual>
<geometry>
<cylinder length="0.1" radius="0.4"/>
<origin rpy="0 0 0" xyz="0 0 0"/>
</geometry>
</visual>
</link>

<joint name="S0J3" type="floating">
<parent link="base_link"/>
<child link="S0L3"/>
</joint>

<link name="S0L4">
<visual>
<geometry>
<cylinder length="0.1" radius="0.4"/>
<origin rpy="0 0 0" xyz="0 0 0"/>
</geometry>
</visual>
</link>

<joint name="S0J4" type="floating">
<parent link="base_link"/>
<child link="S0L4"/>
</joint>

<link name="S0L5">
<visual>
<geometry>
<cylinder length="0.1" radius="0.4"/>
<origin rpy="0 0 0" xyz="0 0 0"/>
</geometry>
</visual>
</link>

<joint name="S0J5" type="floating">
<parent link="base_link"/>
<child link="S0L5"/>
</joint>

<link name="S0L6">
<visual>
<geometry>
<cylinder length="0.1" radius="0.4"/>
<origin rpy="0 0 0" xyz="0 0 0"/>
</geometry>
</visual>
</link>

<joint name="S0J6" type="floating">
<parent link="base_link"/>
<child link="S0L6"/>
</joint>

<link name="S0L7">
<visual>
<geometry>
<cylinder length="0.1" radius="0.4"/>
<origin rpy="0 0 0" xyz="0 0 0"/>
</geometry>
</visual>
</link>

<joint name="S0J7" type="floating">
<parent link="base_link"/>
<child link="S0L7"/>
</joint>

<link name="S0L8">
<visual>
<geometry>
<cylinder length="0.1" radius="0.4"/>
<origin rpy="0 0 0" xyz="0 0 0"/>
</geometry>
</visual>
</link>

<joint name="S0J8" type="floating">
<parent link="base_link"/>
<child link="S0L8"/>
</joint>

<link name="S0L9">
<visual>
<geometry>
<cylinder length="0.1" radius="0.4"/>
<origin rpy="0 0 0" xyz="0 0 0"/>
</geometry>
</visual>
</link>

<joint name="S0J9" type="floating">
<parent link="base_link"/>
<child link="S0L9"/>
</joint>

<link name="S0L10">
<visual>
<geometry>
<cylinder length="0.1" radius="0.4"/>
<origin rpy="0 0 0" xyz="0 0 0"/>
</geometry>
</visual>
</link>

<joint name="S0J10" type="floating">
<parent link="base_link"/>
<child link="S0L10"/>
</joint>

<link name="S0L11">
<visual>
<geometry>
<cylinder length="0.1" radius="0.4"/>
<origin rpy="0 0 0" xyz="0 0 0"/>
</geometry>
</visual>
</link>

<joint name="S0J11" type="floating">
<parent link="base_link"/>
<child link="S0L11"/>
</joint>

<link name="S0L12">
<visual>
<geometry>
<cylinder length="0.1" radius="0.4"/>
<origin rpy="0 0 0" xyz="0 0 0"/>
</geometry>
</visual>
</link>

<joint name="S0J12" type="floating">
<parent link="base_link"/>
<child link="S0L12"/>
</joint>

<link name="S0L13">
<visual>
<geometry>
<cylinder length="0.1" radius="0.4"/>
<origin rpy="0 0 0" xyz="0 0 0"/>
</geometry>
</visual>
</link>

<joint name="S0J13" type="floating">
<parent link="base_link"/>
<child link="S0L13"/>
</joint>

<link name="S0L14">
<visual>
<geometry>
<cylinder length="0.1" radius="0.4"/>
<origin rpy="0 0 0" xyz="0 0 0"/>
</geometry>
</visual>
</link>

<joint name="S0J14" type="floating">
<parent link="base_link"/>
<child link="S0L14"/>
</joint>

<link name="S0L15">
<visual>
<geometry>
<cylinder length="0.1" radius="0.4"/>
<origin rpy="0 0 0" xyz="0 0 0"/>
</geometry>
</visual>
</link>

<joint name="S0J15" type="floating">
<parent link="base_link"/>
<child link="S0L15"/>
</joint>

<link name="S0L16">
<visual>
<geometry>
<cylinder length="0.1" radius="0.4"/>
<origin rpy="0 0 0" xyz="0 0 0"/>
</geometry>
</visual>
</link>

<joint name="S0J16" type="floating">
<parent link="base_link"/>
<child link="S0L16"/>
</joint>

<link name="S0L17">
<visual>
<geometry>
<cylinder length="0.1" radius="0.4"/>
<origin rpy="0 0 0" xyz="0 0 0"/>
</geometry>
</visual>
</link>

<joint name="S0J17" type="floating">
<parent link="base_link"/>
<child link="S0L17"/>
</joint>

<link name="S0L18">
<visual>
<geometry>
<cylinder length="0.1" radius="0.4"/>
<origin rpy="0 0 0" xyz="0 0 0"/>
</geometry>
</visual>
</link>

<joint name="S0J18" type="floating">
<parent link="base_link"/>
<child link="S0L18"/>
</joint>

<link name="S0L19">
<visual>
<geometry>
<cylinder length="0.1" radius="0.4"/>
<origin rpy="0 0 0" xyz="0 0 10"/>
</geometry>
</visual>
</link>

<joint name="S0J19" type="floating">
<parent link="base_link"/>
<child link="S0L19"/>
</joint>

</robot>
