<?xml version="1.0"?>
<robot name="continuum_robot">
<link name="base_link"/>
<material name="while">
<color rgba="0 1 0 1"/>
</material>

<link name="S0L0">
<visual>
<geometry>
<box size="1 1 0.5"/>
<origin rpy="0 0 0" xyz="0 0 0"/>
</geometry>
<material name="white"/>
</visual>
</link>

<joint name="S0J0" type="floating">
<parent link="base_link"/>
<child link="S0L0"/>
</joint>

<link name="S0L1">
<visual>
<geometry>
<cylinder length="0.1" radius="0.4"/>
<origin rpy="0 0 0" xyz="0 0 0"/>
</geometry>
</visual>
</link>

<joint name="S0J1" type="floating">
<parent link="base_link"/>
<child link="S0L1"/>
</joint>

<link name="S0L2">
<visual>
<geometry>
<cylinder length="0.1" radius="0.4"/>
<origin rpy="0 0 0" xyz="0 0 0"/>
</geometry>
</visual>
</link>

<joint name="S0J2" type="floating">
<parent link="base_link"/>
<child link="S0L2"/>
</joint>

<link name="S0L3">
<visual>
<geometry>
<cylinder length="0.1" radius="0.4"/>
<origin rpy="0 0 0" xyz="0 0 0"/>
</geometry>
</visual>
</link>

<joint name="S0J3" type="floating">
<parent link="base_link"/>
<child link="S0L3"/>
</joint>

<link name="S0L4">
<visual>
<geometry>
<cylinder length="0.1" radius="0.4"/>
<origin rpy="0 0 0" xyz="0 0 0"/>
</geometry>
</visual>
</link>

<joint name="S0J4" type="floating">
<parent link="base_link"/>
<child link="S0L4"/>
</joint>

<link name="S0L5">
<visual>
<geometry>
<cylinder length="0.1" radius="0.4"/>
<origin rpy="0 0 0" xyz="0 0 6"/>
</geometry>
</visual>
</link>

<joint name="S0J5" type="floating">
<parent link="base_link"/>
<child link="S0L5"/>
</joint>


<link name="S1L0">
<visual>
<geometry>
<cylinder length="0.1" radius="0.3"/>
<origin rpy="0 0 0" xyz="0 0 0"/>
</geometry>
</visual>
</link>

<joint name="S1J0" type="floating">
<parent link="base_link"/>
<child link="S1L0"/>
</joint>

<link name="S1L1">
<visual>
<geometry>
<cylinder length="0.1" radius="0.3"/>
<origin rpy="0 0 0" xyz="0 0 0"/>
</geometry>
</visual>
</link>

<joint name="S1J1" type="floating">
<parent link="base_link"/>
<child link="S1L1"/>
</joint>

<link name="S1L2">
<visual>
<geometry>
<cylinder length="0.1" radius="0.3"/>
<origin rpy="0 0 0" xyz="0 0 0"/>
</geometry>
</visual>
</link>

<joint name="S1J2" type="floating">
<parent link="base_link"/>
<child link="S1L2"/>
</joint>

<link name="S1L3">
<visual>
<geometry>
<cylinder length="0.1" radius="0.3"/>
<origin rpy="0 0 0" xyz="0 0 0"/>
</geometry>
</visual>
</link>

<joint name="S1J3" type="floating">
<parent link="base_link"/>
<child link="S1L3"/>
</joint>

<link name="S1L4">
<visual>
<geometry>
<cylinder length="0.1" radius="0.3"/>
<origin rpy="0 0 0" xyz="0 0 0"/>
</geometry>
</visual>
</link>

<joint name="S1J4" type="floating">
<parent link="base_link"/>
<child link="S1L4"/>
</joint>

<link name="S1L5">
<visual>
<geometry>
<cylinder length="0.1" radius="0.3"/>
<origin rpy="0 0 0" xyz="0 0 6"/>
</geometry>
</visual>
</link>

<joint name="S1J5" type="floating">
<parent link="base_link"/>
<child link="S1L5"/>
</joint>

</robot>
