<?xml version="1.0"?>
<robot name="continuum_robot">
<link name="base_link"/>
<material name="while">
<color rgba="0 1 0 1"/>
</material>

<link name="S0L0">
<visual>
<geometry>
<box size="1 1 0.5"/>
<origin rpy="0 0 0" xyz="0 0 0"/>
</geometry>
<material name="white"/>
</visual>
</link>

<joint name="S0J0" type="floating">
<parent link="base_link"/>
<child link="S0L0"/>
</joint>

<link name="S0L1">
<visual>
<geometry>
<cylinder length="0.1" radius="0.3"/>
<origin rpy="0 0 0" xyz="0 0 0"/>
</geometry>
</visual>
</link>

<joint name="S0J1" type="floating">
<parent link="base_link"/>
<child link="S0L1"/>
</joint>

<link name="S0L2">
<visual>
<geometry>
<cylinder length="0.1" radius="0.3"/>
<origin rpy="0 0 0" xyz="0 0 0"/>
</geometry>
</visual>
</link>

<joint name="S0J2" type="floating">
<parent link="base_link"/>
<child link="S0L2"/>
</joint>

<link name="S0L3">
<visual>
<geometry>
<cylinder length="0.1" radius="0.3"/>
<origin rpy="0 0 0" xyz="0 0 0"/>
</geometry>
</visual>
</link>

<joint name="S0J3" type="floating">
<parent link="base_link"/>
<child link="S0L3"/>
</joint>

<link name="S0L4">
<visual>
<geometry>
<cylinder length="0.1" radius="0.3"/>
<origin rpy="0 0 0" xyz="0 0 0"/>
</geometry>
</visual>
</link>

<joint name="S0J4" type="floating">
<parent link="base_link"/>
<child link="S0L4"/>
</joint>

<link name="S0L5">
<visual>
<geometry>
<cylinder length="0.1" radius="0.3"/>
<origin rpy="0 0 0" xyz="0 0 0"/>
</geometry>
</visual>
</link>

<joint name="S0J5" type="floating">
<parent link="base_link"/>
<child link="S0L5"/>
</joint>

<link name="S0L6">
<visual>
<geometry>
<cylinder length="0.1" radius="0.3"/>
<origin rpy="0 0 0" xyz="0 0 0"/>
</geometry>
</visual>
</link>

<joint name="S0J6" type="floating">
<parent link="base_link"/>
<child link="S0L6"/>
</joint>

<link name="S0L7">
<visual>
<geometry>
<cylinder length="0.1" radius="0.3"/>
<origin rpy="0 0 0" xyz="0 0 0"/>
</geometry>
</visual>
</link>

<joint name="S0J7" type="floating">
<parent link="base_link"/>
<child link="S0L7"/>
</joint>

<link name="S0L8">
<visual>
<geometry>
<cylinder length="0.1" radius="0.3"/>
<origin rpy="0 0 0" xyz="0 0 0"/>
</geometry>
</visual>
</link>

<joint name="S0J8" type="floating">
<parent link="base_link"/>
<child link="S0L8"/>
</joint>

<link name="S0L9">
<visual>
<geometry>
<cylinder length="0.1" radius="0.3"/>
<origin rpy="0 0 0" xyz="0 0 0"/>
</geometry>
</visual>
</link>

<joint name="S0J9" type="floating">
<parent link="base_link"/>
<child link="S0L9"/>
</joint>

<link name="S0L10">
<visual>
<geometry>
<cylinder length="0.1" radius="0.3"/>
<origin rpy="0 0 0" xyz="0 0 0"/>
</geometry>
</visual>
</link>

<joint name="S0J10" type="floating">
<parent link="base_link"/>
<child link="S0L10"/>
</joint>

<link name="S0L11">
<visual>
<geometry>
<cylinder length="0.1" radius="0.3"/>
<origin rpy="0 0 0" xyz="0 0 0"/>
</geometry>
</visual>
</link>

<joint name="S0J11" type="floating">
<parent link="base_link"/>
<child link="S0L11"/>
</joint>

<link name="S0L12">
<visual>
<geometry>
<cylinder length="0.1" radius="0.3"/>
<origin rpy="0 0 0" xyz="0 0 0"/>
</geometry>
</visual>
</link>

<joint name="S0J12" type="floating">
<parent link="base_link"/>
<child link="S0L12"/>
</joint>

<link name="S0L13">
<visual>
<geometry>
<cylinder length="0.1" radius="0.3"/>
<origin rpy="0 0 0" xyz="0 0 0"/>
</geometry>
</visual>
</link>

<joint name="S0J13" type="floating">
<parent link="base_link"/>
<child link="S0L13"/>
</joint>

<link name="S0L14">
<visual>
<geometry>
<cylinder length="0.1" radius="0.3"/>
<origin rpy="0 0 0" xyz="0 0 0"/>
</geometry>
</visual>
</link>

<joint name="S0J14" type="floating">
<parent link="base_link"/>
<child link="S0L14"/>
</joint>

<link name="S0L15">
<visual>
<geometry>
<cylinder length="0.1" radius="0.3"/>
<origin rpy="0 0 0" xyz="0 0 0"/>
</geometry>
</visual>
</link>

<joint name="S0J15" type="floating">
<parent link="base_link"/>
<child link="S0L15"/>
</joint>

<link name="S0L16">
<visual>
<geometry>
<cylinder length="0.1" radius="0.3"/>
<origin rpy="0 0 0" xyz="0 0 0"/>
</geometry>
</visual>
</link>

<joint name="S0J16" type="floating">
<parent link="base_link"/>
<child link="S0L16"/>
</joint>

<link name="S0L17">
<visual>
<geometry>
<cylinder length="0.1" radius="0.3"/>
<origin rpy="0 0 0" xyz="0 0 0"/>
</geometry>
</visual>
</link>

<joint name="S0J17" type="floating">
<parent link="base_link"/>
<child link="S0L17"/>
</joint>

<link name="S0L18">
<visual>
<geometry>
<cylinder length="0.1" radius="0.3"/>
<origin rpy="0 0 0" xyz="0 0 0"/>
</geometry>
</visual>
</link>

<joint name="S0J18" type="floating">
<parent link="base_link"/>
<child link="S0L18"/>
</joint>

<link name="S0L19">
<visual>
<geometry>
<cylinder length="0.1" radius="0.3"/>
<origin rpy="0 0 0" xyz="0 0 0"/>
</geometry>
</visual>
</link>

<joint name="S0J19" type="floating">
<parent link="base_link"/>
<child link="S0L19"/>
</joint>

<link name="S0L20">
<visual>
<geometry>
<cylinder length="0.1" radius="0.3"/>
<origin rpy="0 0 0" xyz="0 0 0"/>
</geometry>
</visual>
</link>

<joint name="S0J20" type="floating">
<parent link="base_link"/>
<child link="S0L20"/>
</joint>

<link name="S0L21">
<visual>
<geometry>
<cylinder length="0.1" radius="0.3"/>
<origin rpy="0 0 0" xyz="0 0 0"/>
</geometry>
</visual>
</link>

<joint name="S0J21" type="floating">
<parent link="base_link"/>
<child link="S0L21"/>
</joint>

<link name="S0L22">
<visual>
<geometry>
<cylinder length="0.1" radius="0.3"/>
<origin rpy="0 0 0" xyz="0 0 0"/>
</geometry>
</visual>
</link>

<joint name="S0J22" type="floating">
<parent link="base_link"/>
<child link="S0L22"/>
</joint>

<link name="S0L23">
<visual>
<geometry>
<cylinder length="0.1" radius="0.3"/>
<origin rpy="0 0 0" xyz="0 0 0"/>
</geometry>
</visual>
</link>

<joint name="S0J23" type="floating">
<parent link="base_link"/>
<child link="S0L23"/>
</joint>

<link name="S0L24">
<visual>
<geometry>
<cylinder length="0.1" radius="0.3"/>
<origin rpy="0 0 0" xyz="0 0 0"/>
</geometry>
</visual>
</link>

<joint name="S0J24" type="floating">
<parent link="base_link"/>
<child link="S0L24"/>
</joint>

<link name="S0L25">
<visual>
<geometry>
<cylinder length="0.1" radius="0.3"/>
<origin rpy="0 0 0" xyz="0 0 0"/>
</geometry>
</visual>
</link>

<joint name="S0J25" type="floating">
<parent link="base_link"/>
<child link="S0L25"/>
</joint>

<link name="S0L26">
<visual>
<geometry>
<cylinder length="0.1" radius="0.3"/>
<origin rpy="0 0 0" xyz="0 0 0"/>
</geometry>
</visual>
</link>

<joint name="S0J26" type="floating">
<parent link="base_link"/>
<child link="S0L26"/>
</joint>

<link name="S0L27">
<visual>
<geometry>
<cylinder length="0.1" radius="0.3"/>
<origin rpy="0 0 0" xyz="0 0 0"/>
</geometry>
</visual>
</link>

<joint name="S0J27" type="floating">
<parent link="base_link"/>
<child link="S0L27"/>
</joint>

<link name="S0L28">
<visual>
<geometry>
<cylinder length="0.1" radius="0.3"/>
<origin rpy="0 0 0" xyz="0 0 0"/>
</geometry>
</visual>
</link>

<joint name="S0J28" type="floating">
<parent link="base_link"/>
<child link="S0L28"/>
</joint>

<link name="S0L29">
<visual>
<geometry>
<cylinder length="0.1" radius="0.3"/>
<origin rpy="0 0 0" xyz="0 0 5"/>
</geometry>
</visual>
</link>

<joint name="S0J29" type="floating">
<parent link="base_link"/>
<child link="S0L29"/>
</joint>


<link name="S1L0">
<visual>
<geometry>
<cylinder length="0.1" radius="0.3"/>
<origin rpy="0 0 0" xyz="0 0 0"/>
</geometry>
</visual>
</link>

<joint name="S1J0" type="floating">
<parent link="base_link"/>
<child link="S1L0"/>
</joint>

<link name="S1L1">
<visual>
<geometry>
<cylinder length="0.1" radius="0.3"/>
<origin rpy="0 0 0" xyz="0 0 0"/>
</geometry>
</visual>
</link>

<joint name="S1J1" type="floating">
<parent link="base_link"/>
<child link="S1L1"/>
</joint>

<link name="S1L2">
<visual>
<geometry>
<cylinder length="0.1" radius="0.3"/>
<origin rpy="0 0 0" xyz="0 0 0"/>
</geometry>
</visual>
</link>

<joint name="S1J2" type="floating">
<parent link="base_link"/>
<child link="S1L2"/>
</joint>

<link name="S1L3">
<visual>
<geometry>
<cylinder length="0.1" radius="0.3"/>
<origin rpy="0 0 0" xyz="0 0 0"/>
</geometry>
</visual>
</link>

<joint name="S1J3" type="floating">
<parent link="base_link"/>
<child link="S1L3"/>
</joint>

<link name="S1L4">
<visual>
<geometry>
<cylinder length="0.1" radius="0.3"/>
<origin rpy="0 0 0" xyz="0 0 0"/>
</geometry>
</visual>
</link>

<joint name="S1J4" type="floating">
<parent link="base_link"/>
<child link="S1L4"/>
</joint>

<link name="S1L5">
<visual>
<geometry>
<cylinder length="0.1" radius="0.3"/>
<origin rpy="0 0 0" xyz="0 0 0"/>
</geometry>
</visual>
</link>

<joint name="S1J5" type="floating">
<parent link="base_link"/>
<child link="S1L5"/>
</joint>

<link name="S1L6">
<visual>
<geometry>
<cylinder length="0.1" radius="0.3"/>
<origin rpy="0 0 0" xyz="0 0 0"/>
</geometry>
</visual>
</link>

<joint name="S1J6" type="floating">
<parent link="base_link"/>
<child link="S1L6"/>
</joint>

<link name="S1L7">
<visual>
<geometry>
<cylinder length="0.1" radius="0.3"/>
<origin rpy="0 0 0" xyz="0 0 0"/>
</geometry>
</visual>
</link>

<joint name="S1J7" type="floating">
<parent link="base_link"/>
<child link="S1L7"/>
</joint>

<link name="S1L8">
<visual>
<geometry>
<cylinder length="0.1" radius="0.3"/>
<origin rpy="0 0 0" xyz="0 0 0"/>
</geometry>
</visual>
</link>

<joint name="S1J8" type="floating">
<parent link="base_link"/>
<child link="S1L8"/>
</joint>

<link name="S1L9">
<visual>
<geometry>
<cylinder length="0.1" radius="0.3"/>
<origin rpy="0 0 0" xyz="0 0 0"/>
</geometry>
</visual>
</link>

<joint name="S1J9" type="floating">
<parent link="base_link"/>
<child link="S1L9"/>
</joint>

<link name="S1L10">
<visual>
<geometry>
<cylinder length="0.1" radius="0.3"/>
<origin rpy="0 0 0" xyz="0 0 0"/>
</geometry>
</visual>
</link>

<joint name="S1J10" type="floating">
<parent link="base_link"/>
<child link="S1L10"/>
</joint>

<link name="S1L11">
<visual>
<geometry>
<cylinder length="0.1" radius="0.3"/>
<origin rpy="0 0 0" xyz="0 0 0"/>
</geometry>
</visual>
</link>

<joint name="S1J11" type="floating">
<parent link="base_link"/>
<child link="S1L11"/>
</joint>

<link name="S1L12">
<visual>
<geometry>
<cylinder length="0.1" radius="0.3"/>
<origin rpy="0 0 0" xyz="0 0 0"/>
</geometry>
</visual>
</link>

<joint name="S1J12" type="floating">
<parent link="base_link"/>
<child link="S1L12"/>
</joint>

<link name="S1L13">
<visual>
<geometry>
<cylinder length="0.1" radius="0.3"/>
<origin rpy="0 0 0" xyz="0 0 0"/>
</geometry>
</visual>
</link>

<joint name="S1J13" type="floating">
<parent link="base_link"/>
<child link="S1L13"/>
</joint>

<link name="S1L14">
<visual>
<geometry>
<cylinder length="0.1" radius="0.3"/>
<origin rpy="0 0 0" xyz="0 0 0"/>
</geometry>
</visual>
</link>

<joint name="S1J14" type="floating">
<parent link="base_link"/>
<child link="S1L14"/>
</joint>

<link name="S1L15">
<visual>
<geometry>
<cylinder length="0.1" radius="0.3"/>
<origin rpy="0 0 0" xyz="0 0 0"/>
</geometry>
</visual>
</link>

<joint name="S1J15" type="floating">
<parent link="base_link"/>
<child link="S1L15"/>
</joint>

<link name="S1L16">
<visual>
<geometry>
<cylinder length="0.1" radius="0.3"/>
<origin rpy="0 0 0" xyz="0 0 0"/>
</geometry>
</visual>
</link>

<joint name="S1J16" type="floating">
<parent link="base_link"/>
<child link="S1L16"/>
</joint>

<link name="S1L17">
<visual>
<geometry>
<cylinder length="0.1" radius="0.3"/>
<origin rpy="0 0 0" xyz="0 0 0"/>
</geometry>
</visual>
</link>

<joint name="S1J17" type="floating">
<parent link="base_link"/>
<child link="S1L17"/>
</joint>

<link name="S1L18">
<visual>
<geometry>
<cylinder length="0.1" radius="0.3"/>
<origin rpy="0 0 0" xyz="0 0 0"/>
</geometry>
</visual>
</link>

<joint name="S1J18" type="floating">
<parent link="base_link"/>
<child link="S1L18"/>
</joint>

<link name="S1L19">
<visual>
<geometry>
<cylinder length="0.1" radius="0.3"/>
<origin rpy="0 0 0" xyz="0 0 0"/>
</geometry>
</visual>
</link>

<joint name="S1J19" type="floating">
<parent link="base_link"/>
<child link="S1L19"/>
</joint>

<link name="S1L20">
<visual>
<geometry>
<cylinder length="0.1" radius="0.3"/>
<origin rpy="0 0 0" xyz="0 0 0"/>
</geometry>
</visual>
</link>

<joint name="S1J20" type="floating">
<parent link="base_link"/>
<child link="S1L20"/>
</joint>

<link name="S1L21">
<visual>
<geometry>
<cylinder length="0.1" radius="0.3"/>
<origin rpy="0 0 0" xyz="0 0 0"/>
</geometry>
</visual>
</link>

<joint name="S1J21" type="floating">
<parent link="base_link"/>
<child link="S1L21"/>
</joint>

<link name="S1L22">
<visual>
<geometry>
<cylinder length="0.1" radius="0.3"/>
<origin rpy="0 0 0" xyz="0 0 0"/>
</geometry>
</visual>
</link>

<joint name="S1J22" type="floating">
<parent link="base_link"/>
<child link="S1L22"/>
</joint>

<link name="S1L23">
<visual>
<geometry>
<cylinder length="0.1" radius="0.3"/>
<origin rpy="0 0 0" xyz="0 0 0"/>
</geometry>
</visual>
</link>

<joint name="S1J23" type="floating">
<parent link="base_link"/>
<child link="S1L23"/>
</joint>

<link name="S1L24">
<visual>
<geometry>
<cylinder length="0.1" radius="0.3"/>
<origin rpy="0 0 0" xyz="0 0 0"/>
</geometry>
</visual>
</link>

<joint name="S1J24" type="floating">
<parent link="base_link"/>
<child link="S1L24"/>
</joint>

<link name="S1L25">
<visual>
<geometry>
<cylinder length="0.1" radius="0.3"/>
<origin rpy="0 0 0" xyz="0 0 0"/>
</geometry>
</visual>
</link>

<joint name="S1J25" type="floating">
<parent link="base_link"/>
<child link="S1L25"/>
</joint>

<link name="S1L26">
<visual>
<geometry>
<cylinder length="0.1" radius="0.3"/>
<origin rpy="0 0 0" xyz="0 0 0"/>
</geometry>
</visual>
</link>

<joint name="S1J26" type="floating">
<parent link="base_link"/>
<child link="S1L26"/>
</joint>

<link name="S1L27">
<visual>
<geometry>
<cylinder length="0.1" radius="0.3"/>
<origin rpy="0 0 0" xyz="0 0 0"/>
</geometry>
</visual>
</link>

<joint name="S1J27" type="floating">
<parent link="base_link"/>
<child link="S1L27"/>
</joint>

<link name="S1L28">
<visual>
<geometry>
<cylinder length="0.1" radius="0.3"/>
<origin rpy="0 0 0" xyz="0 0 0"/>
</geometry>
</visual>
</link>

<joint name="S1J28" type="floating">
<parent link="base_link"/>
<child link="S1L28"/>
</joint>

<link name="S1L29">
<visual>
<geometry>
<cylinder length="0.1" radius="0.3"/>
<origin rpy="0 0 0" xyz="0 0 10"/>
</geometry>
</visual>
</link>

<joint name="S1J29" type="floating">
<parent link="base_link"/>
<child link="S1L29"/>
</joint>


<link name="S2L0">
<visual>
<geometry>
<cylinder length="0.1" radius="0.2"/>
<origin rpy="0 0 0" xyz="0 0 0"/>
</geometry>
</visual>
</link>

<joint name="S2J0" type="floating">
<parent link="base_link"/>
<child link="S2L0"/>
</joint>

<link name="S2L1">
<visual>
<geometry>
<cylinder length="0.1" radius="0.2"/>
<origin rpy="0 0 0" xyz="0 0 0"/>
</geometry>
</visual>
</link>

<joint name="S2J1" type="floating">
<parent link="base_link"/>
<child link="S2L1"/>
</joint>

<link name="S2L2">
<visual>
<geometry>
<cylinder length="0.1" radius="0.2"/>
<origin rpy="0 0 0" xyz="0 0 0"/>
</geometry>
</visual>
</link>

<joint name="S2J2" type="floating">
<parent link="base_link"/>
<child link="S2L2"/>
</joint>

<link name="S2L3">
<visual>
<geometry>
<cylinder length="0.1" radius="0.2"/>
<origin rpy="0 0 0" xyz="0 0 0"/>
</geometry>
</visual>
</link>

<joint name="S2J3" type="floating">
<parent link="base_link"/>
<child link="S2L3"/>
</joint>

<link name="S2L4">
<visual>
<geometry>
<cylinder length="0.1" radius="0.2"/>
<origin rpy="0 0 0" xyz="0 0 0"/>
</geometry>
</visual>
</link>

<joint name="S2J4" type="floating">
<parent link="base_link"/>
<child link="S2L4"/>
</joint>

<link name="S2L5">
<visual>
<geometry>
<cylinder length="0.1" radius="0.2"/>
<origin rpy="0 0 0" xyz="0 0 6"/>
</geometry>
</visual>
</link>

<joint name="S2J5" type="floating">
<parent link="base_link"/>
<child link="S2L5"/>
</joint>

</robot>
