<?xml version="1.0"?>
<robot name="continuum_robot">
<link name="base_link"/>

<link name="S0L0">
<visual>
<geometry>
<cylinder length="0.1" radius="0.4"/>
<origin rpy="0 0 0" xyz="0 0 0"/>
</geometry>
</visual>
</link>

<joint name="S0J0" type="floating">
<parent link="base_link"/>
<child link="S0L0"/>
</joint>

<link name="S0L1">
<visual>
<geometry>
<cylinder length="0.1" radius="0.4"/>
<origin rpy="0 0 0" xyz="0 0 0"/>
</geometry>
</visual>
</link>

<joint name="S0J1" type="floating">
<parent link="base_link"/>
<child link="S0L1"/>
</joint>

<link name="S0L2">
<visual>
<geometry>
<cylinder length="0.1" radius="0.4"/>
<origin rpy="0 0 0" xyz="0 0 0"/>
</geometry>
</visual>
</link>

<joint name="S0J2" type="floating">
<parent link="base_link"/>
<child link="S0L2"/>
</joint>

<link name="S0L3">
<visual>
<geometry>
<cylinder length="0.1" radius="0.4"/>
<origin rpy="0 0 0" xyz="0 0 0"/>
</geometry>
</visual>
</link>

<joint name="S0J3" type="floating">
<parent link="base_link"/>
<child link="S0L3"/>
</joint>

<link name="S0L4">
<visual>
<geometry>
<cylinder length="0.1" radius="0.4"/>
<origin rpy="0 0 0" xyz="0 0 0"/>
</geometry>
</visual>
</link>

<joint name="S0J4" type="floating">
<parent link="base_link"/>
<child link="S0L4"/>
</joint>

<link name="S0L5">
<visual>
<geometry>
<cylinder length="0.1" radius="0.4"/>
<origin rpy="0 0 0" xyz="0 0 0"/>
</geometry>
</visual>
</link>

<joint name="S0J5" type="floating">
<parent link="base_link"/>
<child link="S0L5"/>
</joint>

<link name="S0L6">
<visual>
<geometry>
<cylinder length="0.1" radius="0.4"/>
<origin rpy="0 0 0" xyz="0 0 0"/>
</geometry>
</visual>
</link>

<joint name="S0J6" type="floating">
<parent link="base_link"/>
<child link="S0L6"/>
</joint>

<link name="S0L7">
<visual>
<geometry>
<cylinder length="0.1" radius="0.4"/>
<origin rpy="0 0 0" xyz="0 0 0"/>
</geometry>
</visual>
</link>

<joint name="S0J7" type="floating">
<parent link="base_link"/>
<child link="S0L7"/>
</joint>

<link name="S0L8">
<visual>
<geometry>
<cylinder length="0.1" radius="0.4"/>
<origin rpy="0 0 0" xyz="0 0 0"/>
</geometry>
</visual>
</link>

<joint name="S0J8" type="floating">
<parent link="base_link"/>
<child link="S0L8"/>
</joint>

<link name="S0L9">
<visual>
<geometry>
<cylinder length="0.1" radius="0.4"/>
<origin rpy="0 0 0" xyz="0 0 5"/>
</geometry>
</visual>
</link>

<joint name="S0J9" type="floating">
<parent link="base_link"/>
<child link="S0L9"/>
</joint>

</robot>
